[2018-05-25 16:54:36,822][Thread-1:7356][task_id:django.request][exception.py:135][ERROR][Internal Server Error: /blog/xiaohei/archive/2018x05/]
Traceback (most recent call last):
  File "C:\Python36\lib\site-packages\django\core\handlers\exception.py", line 41, in inner
    response = get_response(request)
  File "C:\Python36\lib\site-packages\django\core\handlers\base.py", line 187, in _get_response
    response = self.process_exception_by_middleware(e, request)
  File "C:\Python36\lib\site-packages\django\core\handlers\base.py", line 185, in _get_response
    response = wrapped_callback(request, *callback_args, **callback_kwargs)
  File "D:\python10\day78\bbs\blog\views.py", line 281, in home
    year, month = args[1].split("-")
ValueError: not enough values to unpack (expected 2, got 1)
[2018-05-25 16:56:32,723][Thread-1:8112][task_id:blog.views][views.py:290][ERROR][请求访问的日期归档格式不正确！！！]
[2018-05-25 16:56:39,854][Thread-3:6132][task_id:django.request][exception.py:135][ERROR][Internal Server Error: /blog/xiaohei/archive/2018-05-/]
Traceback (most recent call last):
  File "C:\Python36\lib\site-packages\django\core\handlers\exception.py", line 41, in inner
    response = get_response(request)
  File "C:\Python36\lib\site-packages\django\core\handlers\base.py", line 187, in _get_response
    response = self.process_exception_by_middleware(e, request)
  File "C:\Python36\lib\site-packages\django\core\handlers\base.py", line 185, in _get_response
    response = wrapped_callback(request, *callback_args, **callback_kwargs)
  File "D:\python10\day78\bbs\blog\views.py", line 282, in home
    year, month = args[1].split("-")
ValueError: too many values to unpack (expected 2)
[2018-05-28 10:47:42,388][Thread-12:5696][task_id:django.request][exception.py:135][ERROR][Internal Server Error: /blog/up_down/]
Traceback (most recent call last):
  File "C:\Python36\lib\site-packages\django\core\handlers\exception.py", line 41, in inner
    response = get_response(request)
  File "C:\Python36\lib\site-packages\django\core\handlers\base.py", line 187, in _get_response
    response = self.process_exception_by_middleware(e, request)
  File "C:\Python36\lib\site-packages\django\core\handlers\base.py", line 185, in _get_response
    response = wrapped_callback(request, *callback_args, **callback_kwargs)
  File "D:\python10\day78\bbs\blog\views.py", line 349, in up_down
    models.ArticleUpDown.objects.create(user=user,article_id=article_id,is_up=is_up)
  File "C:\Python36\lib\site-packages\django\db\models\manager.py", line 85, in manager_method
    return getattr(self.get_queryset(), name)(*args, **kwargs)
  File "C:\Python36\lib\site-packages\django\db\models\query.py", line 392, in create
    obj = self.model(**kwargs)
  File "C:\Python36\lib\site-packages\django\db\models\base.py", line 555, in __init__
    _setattr(self, field.name, rel_obj)
  File "C:\Python36\lib\site-packages\django\db\models\fields\related_descriptors.py", line 216, in __set__
    self.field.remote_field.model._meta.object_name,
ValueError: Cannot assign "<SimpleLazyObject: <django.contrib.auth.models.AnonymousUser object at 0x000000000BDAE9B0>>": "ArticleUpDown.user" must be a "UserInfo" instance.
